Workbook

Sheet Scholar
A1: Title | B1: Link | C1: Pubblication Class | D1: Q1 | E1: Q2 | F1: Q3 | G1: Q4 | H1: Q5 | I1: Q6 | J1: Q7 | K1: Exc.Crit | L1: Inc.Crit | M1: Pubblication Venue | N1: Vanue Name | O1: IDQ | P1: CDQ | Q1: FDQ | R1: Selected
A2: A New Smart Contract Anomaly Detection Method by Fusing Opcode and Source Code Features for Blockchain Services | B2: https://ieeexplore.ieee.org/abstract/document/10130487 | C2: PS | D2: =Info!$B$51 -> 0 | E2: =Info!$B$53 -> 1 | L2: 2 | M2: Journal Article | N2: IEEE Transactions on Network and Service Management | O2: 1 | P2: =(D2+E2)/2 -> 0.5 | Q2: =(O2+P2)/2 -> 0.75 | R2: =IF(_xlfn.BITAND(P2>0.4999, Q2>0.4999)=1,1,0) -> 1
A3: A Novel Smart Contract Vulnerability Detection Method Based on Information Graph and Ensemble Learning | B3: https://www.mdpi.com/1424-8220/22/9/3581 | C3: PS | D3: =Info!$B$16 -> 1 | E3: =Info!$B$53 -> 1 | L3: 1 | M3: Journal Article | N3: Sensors | O3: 0.8 | P3: =(D3+E3)/2 -> 1 | Q3: =(O3+P3)/2 -> 0.9 | R3: =IF(_xlfn.BITAND(P3>0.4999, Q3>0.4999)=1,1,0) -> 1
A4: A survey on smart contract vulnerabilities: Data sources, detection and repair | B4: https://www.sciencedirect.com/science/article/pii/S0950584923000757 | C4: Survey | D4: =Info!$B$16 -> 1 | E4: =Info!$B$19 -> 1 | F4: =Info!$B$25 -> 0.6 | G4: =Info!$B$31 -> 0.3 | H4: =Info!$B$37 -> 0 | I4: =Info!$B$40 -> 0 | J4: =Info!$B$42 -> 1 | L4: 1 | M4: Journal Article | N4: Information and Software Technology | O4: 1 | P4: =(D4+E4+F4+G4+H4+I4+J4)/6 -> 0.65 | Q4: =(O4+P4)/2 -> 0.825 | R4: =IF(_xlfn.BITAND(P4>0.4999, Q4>0.4999)=1,1,0) -> 1
A5: A systematic literature review of undiscovered vulnerabilities and tools in smart contract technology | B5: https://www.degruyter.com/document/doi/10.1515/jisys-2023-0038/html | C5: SLR | D5: =Info!$B$16 -> 1 | E5: =Info!$B$19 -> 1 | F5: =Info!$B$24 -> 1 | G5: =Info!$B$29 -> 1 | H5: =Info!$B$35 -> 0.6 | I5: =Info!$B$40 -> 0 | J5: =Info!$B$42 -> 1 | L5: 1,2,3 | M5: Journal Article | N5: Journal of Intelligent Systems | O5: 0.8 | P5: =(D5+E5+F5+G5+H5+I5+J5)/6 -> 0.93333333 | Q5: =(O5+P5)/2 -> 0.86666667 | R5: =IF(_xlfn.BITAND(P5>0.4999, Q5>0.4999)=1,1,0) -> 1
A6: ASSBert: Active and semi-supervised bert for smart contract vulnerability detection | B6: https://www.sciencedirect.com/science/article/pii/S221421262300008X?casa_token=L17-2HJTgKsAAAAA:23B-zr-DrCcMyTvK3pFKbj39IVgciQFPTp_DaQSmLk8oOziBxuzZ7HZ2uvb-4gb_A9oGJQHW | C6: PS | D6: =Info!$B$49 -> 0.6 | E6: =Info!$B$53 -> 1 | L6: 2,3 | M6: Journal Article | N6: Journal of Information Security and Applications | O6: 1 | P6: =(D6+E6)/2 -> 0.8 | Q6: =(O6+P6)/2 -> 0.9 | R6: =IF(_xlfn.BITAND(P6>0.4999, Q6>0.4999)=1,1,0) -> 1
A7: AUTOMATED MUTATION ANALYSIS FOR SMART CONTRACT USING AMA TOOL WITH ENHANCED GA AND MACHINE LEARNING APPROACH | B7: https://www.jatit.org/volumes/Vol101No21/22Vol101No21.pdf | C7: PS | D7: =Info!$B$51 -> 0 | E7: =Info!$B$53 -> 1 | L7: 2 | M7: Journal Article | N7: Journal of Theoretical and Applied Information Technology | O7: 0.5 | P7: =(D7+E7)/2 -> 0.5 | Q7: =(O7+P7)/2 -> 0.5 | R7: =IF(_xlfn.BITAND(P7>0.4999, Q7>0.4999)=1,1,0) -> 1
A8: Automation and smart materials in detecting smart contracts vulnerabilities in Blockchain using deep learning | B8: https://www.sciencedirect.com/science/article/pii/S2214785321030273?casa_token=iI8eqBHd0dAAAAAA:IsrBBuibA8NSlZ2kPSsIOCioFA4YnsqFasV7Uz0FasX4NaFgid2wbeF7pHvjC-05SulB-Rii | C8: PS | D8: =Info!$B$48 -> 1 | E8: =Info!$B$54 -> 0 | L8: 2,3 | M8: Journal Article | N8: Materials Today: Proceedings | O8: 0.8 | P8: =(D8+E8)/2 -> 0.5 | Q8: =(O8+P8)/2 -> 0.65 | R8: =IF(_xlfn.BITAND(P8>0.4999, Q8>0.4999)=1,1,0) -> 1
A9: AutoMESC: Automatic Framework for Mining and Classifying Ethereum Smart Contract Vulnerabilities and Their Fixes | B9: https://ieeexplore.ieee.org/abstract/document/10371421?casa_token=mSO-2-SQH6wAAAAA:TxW1DRrUmpfyKVVIY9sJfnUq6o24yaXucDPJ7Q-RuH778THgkvPEOJ9lbptgqemmDqQ1M-s | C9: PS | D9: =Info!$B$51 -> 0 | E9: =Info!$B$53 -> 1 | L9: 2 | M9: Conference Proceeding or Workshop | N9: Euromicro Conference on Software Engineering and Advanced Applications | O9: 0.5 | P9: =(D9+E9)/2 -> 0.5 | Q9: =(O9+P9)/2 -> 0.5 | R9: =IF(_xlfn.BITAND(P9>0.4999, Q9>0.4999)=1,1,0) -> 1
A10: Data Flow-driven and Attention Mechanism-enabled Smart Contract Vulnerability Detection for Secure and Green Blockchain-based Service Networks | B10: https://ieeexplore.ieee.org/abstract/document/10279381 | C10: PS | D10: =Info!$B$51 -> 0 | E10: =Info!$B$53 -> 1 | L10: 2 | M10: Conference Proceeding or Workshop | N10: IEEE International Conference on Communications (ICC) | O10: 1 | P10: =(D10+E10)/2 -> 0.5 | Q10: =(O10+P10)/2 -> 0.75 | R10: =IF(_xlfn.BITAND(P10>0.4999, Q10>0.4999)=1,1,0) -> 1
A11: Demystifying Random Number in Ethereum Smart Contract: Taxonomy, Vulnerability Identification, and Attack Detection | B11: https://ieeexplore.ieee.org/abstract/document/10111037?casa_token=QEdDIblGokYAAAAA:0B4lB52irnYXlCYtNceVkNaGiA5hElARm1S8YLbzMMQtbyF5ZRpIQp76i-3VF9gQPwTO31g | C11: PS | D11: =Info!$B$50 -> 0.3 | E11: =Info!$B$53 -> 1 | L11: 1 | M11: Journal Article | N11: IEEE Transactions on Software Engineering | O11: 1 | P11: =(D11+E11)/2 -> 0.65 | Q11: =(O11+P11)/2 -> 0.825 | R11: =IF(_xlfn.BITAND(P11>0.4999, Q11>0.4999)=1,1,0) -> 1
A12: Design and evaluation of highly accurate smart contract code vulnerability detection framework | B12: https://link.springer.com/article/10.1007/s10618-023-00981-1 | C12: PS | D12: =Info!$B$51 -> 0 | E12: =Info!$B$53 -> 1 | L12: 1.2 | M12: Journal Article | N12: Data Mining and Knowledge Discovery | O12: 1 | P12: =(D12+E12)/2 -> 0.5 | Q12: =(O12+P12)/2 -> 0.75 | R12: =IF(_xlfn.BITAND(P12>0.4999, Q12>0.4999)=1,1,0) -> 1
A13: Detecting functional and security-related issues in smartcontracts: A systematic literature review | B13: https://onlinelibrary.wiley.com/doi/epdf/10.1002/spe.3156 | C13: SLR | D13: =Info!$B$16 -> 1 | E13: =Info!$B$21 -> 0.3 | F13: =Info!$B$26 -> 0.3 | G13: =Info!$B$29 -> 1 | H13: =Info!$B$34 -> 1 | I13: =Info!$B$39 -> 1 | J13: =Info!$B$43 -> 0.5 | L13: 1.2 | M13: Journal Article | N13: Software - Practice and Experience | O13: 0.8 | P13: =(D13+E13+F13+G13+H13+I13+J13)/7 -> 0.72857143 | Q13: =(O13+P13)/2 -> 0.76428571 | R13: =IF(_xlfn.BITAND(P13>0.4999, Q13>0.4999)=1,1,0) -> 1
A14: EDIT: A data inspection tool for smart contracts temporal behavior modeling and prediction | B14: https://www.sciencedirect.com/science/article/pii/S0167739X24000013 | C14: PS | D14: =Info!$B$51 -> 0 | E14: =Info!$B$53 -> 1 | L14: 2,3 | M14: Journal Article | N14: Future Generation Computer Systems | O14: 1 | P14: =(D14+E14)/2 -> 0.5 | Q14: =(O14+P14)/2 -> 0.75 | R14: =IF(_xlfn.BITAND(P14>0.4999, Q14>0.4999)=1,1,0) -> 1
A15: Empirical Review of Smart Contract and DeFi Security: Vulnerability Detection and Automated Repair | B15: https://arxiv.org/abs/2309.02391 | C15: Survey | D15: =Info!$B$17 -> 0 | E15: =Info!$B$19 -> 1 | F15: =Info!$B$25 -> 0.6 | G15: =Info!$B$29 -> 1 | H15: =Info!$B$34 -> 1 | I15: =Info!$B$39 -> 1 | J15: =Info!$B$42 -> 1 | L15: 1.3 | M15: Arxiv Paper or Preprint | O15: 0.2 | P15: =(D15+E15+F15+G15+H15+I15+J15)/7 -> 0.8 | Q15: =(O15+P15)/2 -> 0.5 | R15: =IF(_xlfn.BITAND(P15>0.4999, Q15>0.4999)=1,1,0) -> 1
A16: Enhancing Smart-Contract Security through Machine Learning: A Survey of Approaches and Techniques | B16: https://www.mdpi.com/2079-9292/12/9/2046 | C16: Survey | D16: =Info!$B$17 -> 0 | E16: =Info!$B$20 -> 0.6 | F16: =Info!$B$26 -> 0.3 | G16: =Info!$B$30 -> 0.6 | H16: =Info!$B$35 -> 0.6 | I16: =Info!$B$40 -> 0 | J16: =Info!$B$42 -> 1 | L16: 1 | M16: Journal Article | N16: Electronics | O16: 0.8 | P16: =(D16+E16+F16+G16+H16+I16+J16)/6 -> 0.51666667 | Q16: =(O16+P16)/2 -> 0.65833333 | R16: =IF(_xlfn.BITAND(P16>0.4999, Q16>0.4999)=1,1,0) -> 1
A17: ESCORT: Ethereum Smart COntRacTs Vulnerability Detection using Deep Neural Network and Transfer Learning | B17: https://arxiv.org/abs/2103.12607 | C17: PS | D17: 1 | E17: 1 | L17: 2 | M17: Arxiv Paper or Preprint | O17: 0.2 | P17: =(D17+E17)/2 -> 1 | Q17: =(O17+P17)/2 -> 0.6 | R17: =IF(_xlfn.BITAND(P17>0.4999, Q17>0.4999)=1,1,0) -> 1
A18: EtherProv: Provenance-Aware Detection, Analysis, and Mitigation of Ethereum Smart Contract Security Issues | B18: https://ieeexplore.ieee.org/abstract/document/9680507?casa_token=EvobFcapGO8AAAAA:77f_1k1cz7PPbn_R-F_IJdxxZf7jSADmcjNxkRh-oNewQmKb3GQK9IwdCv1A8Ikm6fWqoRE | C18: PS | D18: =Info!$B$49 -> 0.6 | E18: =Info!$B$53 -> 1 | L18: 1 | M18: Conference Proceeding or Workshop | N18: IEEE International Conference on Blockchain | O18: 0.2 | P18: =(D18+E18)/2 -> 0.8 | Q18: =(O18+P18)/2 -> 0.5 | R18: =IF(_xlfn.BITAND(P18>0.4999, Q18>0.4999)=1,1,0) -> 1
A19: GraphSA: Smart Contract Vulnerability Detection Combining Graph Neural Networks and Static Analysis | B19: https://ebooks.iospress.nl/doi/10.3233/FAIA230374 | C19: PS | D19: =Info!$B$17 -> 0 | E19: =Info!$B$53 -> 1 | L19: 2,3 | M19: Book Section | N19: IOS Press | O19: 1 | P19: =(D19+E19)/2 -> 0.5 | Q19: =(O19+P19)/2 -> 0.75 | R19: =IF(_xlfn.BITAND(P19>0.4999, Q19>0.4999)=1,1,0) -> 1
A20: GRATDet: Smart Contract Vulnerability Detector Based on Graph Representation and Transformer | B20: https://cdn.techscience.cn/files/cmc/2023/TSP_CMC-76-2/TSP_CMC_38878/TSP_CMC_38878.pdf | C20: PS | D20: =Info!$B$51 -> 0 | E20: =Info!$B$53 -> 1 | L20: 2 | M20: Journal Article | N20: Computers, Materials & Continua | O20: 0.8 | P20: =(D20+E20)/2 -> 0.5 | Q20: =(O20+P20)/2 -> 0.65 | R20: =IF(_xlfn.BITAND(P20>0.4999, Q20>0.4999)=1,1,0) -> 1
A21: Improvement and Optimization of Vulnerability Detection Methods for Ethernet Smart Contracts | B21: https://ieeexplore.ieee.org/abstract/document/10192903 | C21: PS | D21: =Info!$B$17 -> 0 | E21: =Info!$B$20 -> 0.6 | F21: =Info!$B$26 -> 0.3 | G21: =Info!$B$30 -> 0.6 | H21: =Info!$B$35 -> 0.6 | I21: =Info!$B$40 -> 0 | J21: =Info!$B$42 -> 1 | L21: 2 | M21: Journal Article | N21: IEEE Access | O21: 1 | P21: =(D21+E21+F21+G21+H21+I21+J21)/6 -> 0.51666667 | Q21: =(O21+P21)/2 -> 0.75833333 | R21: =IF(_xlfn.BITAND(P21>0.4999, Q21>0.4999)=1,1,0) -> 1
A22: MSmart: Smart Contract Vulnerability Analysis and Improved Strategies Based on Smartcheck | B22: https://www.mdpi.com/2076-3417/13/3/1733 | C22: PS | D22: =Info!$B$51 -> 0 | E22: =Info!$B$53 -> 1 | L22: 2 | M22: Journal Article | N22: Applied Science | O22: 0.5 | P22: =(D22+E22)/2 -> 0.5 | Q22: =(O22+P22)/2 -> 0.5 | R22: =IF(_xlfn.BITAND(P22>0.4999, Q22>0.4999)=1,1,0) -> 1
A23: ReSuMo: a regression strategy and tool for mutation testing of solidity smart contracts | B23: https://link.springer.com/article/10.1007/s11219-023-09637-1 | C23: PS | D23: =Info!$B$17 -> 0 | E23: =Info!$B$53 -> 1 | L23: 2,3 | M23: Journal Article | N23: Software Quality Journal | O23: 0.5 | P23: =(D23+E23)/2 -> 0.5 | Q23: =(O23+P23)/2 -> 0.5 | R23: =IF(_xlfn.BITAND(P23>0.4999, Q23>0.4999)=1,1,0) -> 1
A24: SCGRU: A Model for Ethereum Smart Contract Vulnerability Detection Combining CNN and BiGRU-Attention | B24: https://ieeexplore.ieee.org/abstract/document/10270857 | C24: PS | D24: =Info!$B$17 -> 0 | E24: =Info!$B$53 -> 1 | L24: 2,3 | M24: Conference Proceeding or Workshop | N24: IEEE International Conference on Signal and Image Processing (ICSIP) | O24: 0.5 | P24: =(D24+E24)/2 -> 0.5 | Q24: =(O24+P24)/2 -> 0.5 | R24: =IF(_xlfn.BITAND(P24>0.4999, Q24>0.4999)=1,1,0) -> 1
A25: Security Risks and Best Practices for Blockchain and Smart Contracts: A Systematic Literature Review | B25: https://ieeexplore.ieee.org/abstract/document/10278055 | C25: SLR | D25: =Info!$B$16 -> 1 | E25: =Info!$B$20 -> 0.6 | F25: =Info!$B$25 -> 0.6 | G25: =Info!$B$32 -> 0 | H25: =Info!$B$37 -> 0 | I25: =Info!$B$40 -> 0 | J25: =Info!$B$42 -> 1 | L25: 1 | M25: Conference Proceeding or Workshop | N25: International Conference on Information Management and Technology (ICIMTech) | O25: 1 | P25: =(D25+E25+F25+G25+H25+I25+J25)/6 -> 0.53333333 | Q25: =(O25+P25)/2 -> 0.76666667 | R25: =IF(_xlfn.BITAND(P25>0.4999, Q25>0.4999)=1,1,0) -> 1
A26: Smart Contract and DeFi Security Tools: Do They Meet the Needs of Practitioners? | B26: https://synthical.com/article/ed404388-ffad-11ed-9b54-72eb57fa10b3 | C26: Survey | D26: 1 | E26: 1 | F26: 0.6 | G26: 0.3 | H26: 0.6 | I26: 0 | J26: 1 | L26: 1 | M26: Conference Proceeding or Workshop | N26: IEEE/ACM International Conference on Software Engineering | O26: 1 | P26: =(D26+E26+F26+G26+H26+I26+J26)/7 -> 0.64285714 | Q26: =(O26+P26)/2 -> 0.82142857 | R26: =IF(_xlfn.BITAND(P26>0.4999, Q26>0.4999)=1,1,0) -> 1
A27: Smart Contracts Security Threats and Solutions | B27: https://www.igi-global.com/gateway/article/full-text-pdf/304048&riu=true | C27: SLR | D27: =Info!$B$16 -> 1 | E27: =Info!$B$20 -> 0.6 | F27: =Info!$B$24 -> 1 | G27: =Info!$B$32 -> 0 | H27: =Info!$B$37 -> 0 | I27: =Info!$B$40 -> 0 | J27: =Info!$B$43 -> 0.5 | L27: 1 | M27: Journal Article | N27: International Journal of Information Technology and Web Engineering | O27: 0.5 | P27: =(D27+E27+F27+G27+H27+I27+J27)/6 -> 0.51666667 | Q27: =(O27+P27)/2 -> 0.50833333 | R27: =IF(_xlfn.BITAND(P27>0.4999, Q27>0.4999)=1,1,0) -> 1
A28: SmartFast: an accurate and robust formal analysis tool for Ethereum smart contracts | B28: https://link.springer.com/article/10.1007/s10664-022-10218-2 | C28: PS | D28: =Info!$B$50 -> 0.3 | E28: =Info!$B$53 -> 1 | L28: 2,3 | M28: Journal Article | N28: Empirical Software Engineering | O28: 1 | P28: =(D28+E28)/2 -> 0.65 | Q28: =(O28+P28)/2 -> 0.825 | R28: =IF(_xlfn.BITAND(P28>0.4999, Q28>0.4999)=1,1,0) -> 1
A29: SuMo: A mutation testing approach and tool for the Ethereum blockchain | B29: https://www.sciencedirect.com/science/article/pii/S0164121222001418 | C29: PS | D29: =Info!$B$49 -> 0.6 | E29: =Info!$B$53 -> 1 | L29: 2,3 | M29: Journal Article | N29: Journal of Systems and Software | O29: 1 | P29: =(D29+E29)/2 -> 0.8 | Q29: =(O29+P29)/2 -> 0.9 | R29: =IF(_xlfn.BITAND(P29>0.4999, Q29>0.4999)=1,1,0) -> 1
A30: Systematic Review of Ethereum Smart Contract Security Vulnerabilities, Analysis Methods and Tools | B30: https://web.archive.org/web/20210909005434id_/https://repositum.tuwien.at/bitstream/20.500.12708/18323/1/Rameder%20Heidelinde%20-%202021%20-%20Systematic%20Review%20of%20Ethereum%20Smart%20Contract...pdf | C30: SLR | D30: =Info!$B$16 -> 1 | E30: =Info!$B$16 -> 1 | F30: =Info!$B$24 -> 1 | G30: =Info!$B$29 -> 1 | H30: =Info!$B$34 -> 1 | I30: =Info!$B$39 -> 1 | J30: =Info!$B$44 -> 0 | L30: 1,2,3 | M30: Thesis or Seminar Paper | N30: PhD Thesis | O30: 0.2 | P30: =(D30+E30+F30+G30+H30+I30+J30)/7 -> 0.85714286 | Q30: =(O30+P30)/2 -> 0.52857143 | R30: =IF(_xlfn.BITAND(P30>0.4999, Q30>0.4999)=1,1,0) -> 1
A31: The State of Ethereum Smart Contracts Security: Vulnerabilities, Countermeasures, and Tool Support | B31: https://www.mdpi.com/2624-800X/2/2/19 | C31: Survey | D31: =Info!$B$17 -> 0 | E31: =Info!$B$19 -> 1 | F31: =Info!$B$24 -> 1 | G31: =Info!$B$30 -> 0.6 | H31: =Info!$B$35 -> 0.6 | I31: =Info!$B$39 -> 1 | J31: =Info!$B$43 -> 0.5 | L31: 1 | M31: Journal Article | N31: Journal of Cybersecurity and Privacy | O31: 0.5 | P31: =(D31+E31+F31+G31+H31+I31+J31)/7 -> 0.67142857 | Q31: =(O31+P31)/2 -> 0.58571429 | R31: =IF(_xlfn.BITAND(P31>0.4999, Q31>0.4999)=1,1,0) -> 1
A32: Towards the Assessment and the Improvement of Smart Contract Security | B32: https://flore.unifi.it/handle/2158/1272428 | C32: Survey | D32: =Info!$B$16 -> 1 | E32: =Info!$B$19 -> 1 | F32: =Info!$B$24 -> 1 | G32: =Info!$B$29 -> 1 | H32: =Info!$B$34 -> 1 | I32: =Info!$B$40 -> 0 | J32: =Info!$B$43 -> 0.5 | L32: 1 | M32: Thesis or Seminar Paper | N32: Thesis | O32: 0.2 | P32: =(D32+E32+F32+G32+H32+I32+J32)/6 -> 0.91666667 | Q32: =(O32+P32)/2 -> 0.55833333 | R32: =IF(_xlfn.BITAND(P32>0.4999, Q32>0.4999)=1,1,0) -> 1
A33: Unveiling the Landscape of Smart Contract Vulnerabilities: A Detailed Examination and Codification of Vulnerabilities in Prominent Blockchains | B33: https://papers.ssrn.com/sol3/papers.cfm?abstract_id=4650383 | C33: Survey | D33: =Info!$B$17 -> 0 | E33: =Info!$B$19 -> 1 | F33: =Info!$B$24 -> 1 | G33: =Info!$B$32 -> 0 | H33: =Info!$B$37 -> 0 | I33: =Info!$B$39 -> 1 | J33: =Info!$B$42 -> 1 | L33: 1 | M33: Journal Article | N33: International Journal of Computer Networks & Communications (IJCNC) | O33: 0.5 | P33: =(D33+E33+F33+G33+H33+I33+J33)/7 -> 0.57142857 | Q33: =(O33+P33)/2 -> 0.53571429 | R33: =IF(_xlfn.BITAND(P33>0.4999, Q33>0.4999)=1,1,0) -> 1
A34: Vulnerability and Transaction Behavior Based Detection of Malicious Smart Contracts | B34: https://link.springer.com/chapter/10.1007/978-3-030-94029-4_6 | C34: Survey | D34: =Info!$B$16 -> 1 | E34: =Info!$B$19 -> 1 | F34: =Info!$B$24 -> 1 | G34: =Info!$B$30 -> 0.6 | H34: =Info!$B$36 -> 0.3 | I34: =Info!$B$40 -> 0 | J34: =Info!$B$43 -> 0.5 | L34: 2 | M34: Conference Proceeding or Workshop | N34: Cyberspace Safety and Security | O34: 0.4 | P34: =(D34+E34+F34+G34+H34+I34+J34)/6 -> 0.73333333 | Q34: =(O34+P34)/2 -> 0.56666667 | R34: =IF(_xlfn.BITAND(P34>0.4999, Q34>0.4999)=1,1,0) -> 1
A35: ConvMHSA-SCVD: Enhancing Smart Contract Vulnerability Detection through a Knowledge-Driven and Data-Driven Framework | B35: https://ieeexplore.ieee.org/abstract/document/10301256 | C35: PS | D35: =Info!$B$51 -> 0 | E35: =Info!$B$53 -> 1 | L35: 2 | M35: Conference Proceeding or Workshop | N35: International Symposium on Software Reliability Engineering (ISSRE) | O35: 0.4 | P35: =(D35+E35)/2 -> 0.5 | Q35: =(O35+P35)/2 -> 0.45 | R35: =IF(_xlfn.BITAND(P35>0.4999, Q35>0.4999)=1,1,0) -> 0
A36: Contextual Language Model and Transfer Learning for Reentrancy Vulnerability Detection in Smart Contracts | B36: https://dl.acm.org/doi/abs/10.1145/3628797.3628945 | C36: PS | D36: =Info!$B$51 -> 0 | E36: =Info!$B$54 -> 0 | L36: 2 | M36: Conference Proceeding or Workshop | N36: SOICT '23: Proceedings of the 12th International Symposium on Information and Communication Technology | O36: 0.4 | P36: =(D36+E36)/2 -> 0 | Q36: =(O36+P36)/2 -> 0.2 | R36: =IF(_xlfn.BITAND(P36>0.4999, Q36>0.4999)=1,1,0) -> 0
A37: A Smart Contract Vulnerability Detection Model Based on Syntactic and Semantic Fusion Learning | B37: https://www.hindawi.com/journals/wcmc/2023/9212269/ | C37: PS | D37: =Info!$B$51 -> 0 | E37: =Info!$B$54 -> 0 | L37: 2 | M37: Journal Article | N37: Wireless Communications and Mobile Computing | O37: 0.8 | P37: =(D37+E37)/2 -> 0 | Q37: =(O37+P37)/2 -> 0.4 | R37: =IF(_xlfn.BITAND(P37>0.4999, Q37>0.4999)=1,1,0) -> 0
A38: Smart contract vulnerability detection based on a semantic code structure and a self-designed neural network | B38: https://www.sciencedirect.com/science/article/pii/S0045790623001908 | C38: PS | D38: =Info!$B$51 -> 0 | E38: =Info!$B$54 -> 0 | L38: 2 | M38: Journal Article | N38: Computers and Electrical Engineering | O38: 1 | P38: =(D38+E38)/2 -> 0 | Q38: =(O38+P38)/2 -> 0.5 | R38: =IF(_xlfn.BITAND(P38>0.4999, Q38>0.4999)=1,1,0) -> 0
A39: A Smart Contract Vulnerability Detection Method Based on Multimodal Feature Fusion and Deep Learning | B39: https://www.mdpi.com/2227-7390/11/23/4823 | C39: PS | D39: =Info!$B$51 -> 0 | E39: =Info!$B$54 -> 0 | L39: 2 | M39: Journal Article | N39: Mathematics | O39: 1 | P39: =(D39+E39)/2 -> 0 | Q39: =(O39+P39)/2 -> 0.5 | R39: =IF(_xlfn.BITAND(P39>0.4999, Q39>0.4999)=1,1,0) -> 0
A40: Detecting Smart Contract Vulnerabilities with Combined Binary and Multiclass Classification | B40: https://www.mdpi.com/2410-387X/7/3/34 | C40: PS | D40: =Info!$B$51 -> 0 | E40: =Info!$B$54 -> 0 | L40: 2 | M40: Journal Article | N40: Cryptography | O40: 0.8 | P40: =(D40+E40)/2 -> 0 | Q40: =(O40+P40)/2 -> 0.4 | R40: =IF(_xlfn.BITAND(P40>0.4999, Q40>0.4999)=1,1,0) -> 0
...

Sheet ACM_DL
A1: Title | B1: Link | C1: Pubblication Class | D1: Q1 | E1: Q2 | F1: Q3 | G1: Q4 | H1: Q5 | I1: Q6 | J1: Q7 | K1: Exc.Crit | L1: Inc.Crit | M1: Pubblication Venue | N1: Vanue Name | O1: IDQ | P1: CDQ | Q1: FDQ | R1: Selected
A2: A Solicitous Approach to Smart Contract Verification | B2: https://dl.acm.org/doi/10.1145/3564699 | C2: PS | D2: =Info!$B$50 -> 0.3 | E2: =Info!$B$53 -> 1 | L2: 2,3 | M2: Journal Article | N2: ACM Transactions on Privacy and Security | O2: 1 | P2: =(D2+E2)/2 -> 0.65 | Q2: =(O2+P2)/2 -> 0.825 | R2: =IF(_xlfn.BITAND(P2>0.4999, Q2>0.4999)=1,1,0) -> 1
A3: AChecker: Statically Detecting Smart Contract Access Control Vulnerabilities | B3: https://dl.acm.org/doi/10.1109/ICSE48619.2023.00087 | C3: PS | D3: =Info!$B$50 -> 0.3 | E3: =Info!$B$53 -> 1 | L3: 2,3 | M3: Conference Proceeding or Workshop | N3: ICSE '23: Proceedings of the 45th International Conference on Software Engineering | O3: 1 | P3: =(D3+E3)/2 -> 0.65 | Q3: =(O3+P3)/2 -> 0.825 | R3: =IF(_xlfn.BITAND(P3>0.4999, Q3>0.4999)=1,1,0) -> 1
A4: Cross-Modality Mutual Learning for Enhancing Smart Contract Vulnerability Detection on Bytecode | B4: https://dl.acm.org/doi/10.1145/3543507.3583367 | C4: PS | D4: =Info!$B$51 -> 0 | E4: =Info!$B$53 -> 1 | L4: 2 | M4: Conference Proceeding or Workshop | N4: WWW '23: Proceedings of the ACM Web Conference 2023 | O4: 1 | P4: =(D4+E4)/2 -> 0.5 | Q4: =(O4+P4)/2 -> 0.75 | R4: =IF(_xlfn.BITAND(P4>0.4999, Q4>0.4999)=1,1,0) -> 1
A5: Turn the Rudder: A Beacon of Reentrancy Detection for Smart Contracts on Ethereum | B5: https://dl.acm.org/doi/10.1109/ICSE48619.2023.00036 | C5: Survey | D5: =Info!$B$17 -> 0 | E5: =Info!$B$20 -> 0.6 | F5: =Info!$B$25 -> 0.6 | G5: =Info!$B$30 -> 0.6 | H5: =Info!$B$36 -> 0.3 | I5: =Info!$B$40 -> 0 | J5: =Info!$B$42 -> 1 | L5: 2 | M5: Conference Proceeding or Workshop | N5: ICSE '23: Proceedings of the 45th International Conference on Software Engineering | O5: 1 | P5: =(D5+E5+F5+G5+H5+I5+J5)/6 -> 0.51666667 | Q5: =(O5+P5)/2 -> 0.75833333 | R5: =IF(_xlfn.BITAND(P5>0.4999, Q5>0.4999)=1,1,0) -> 1
A6: Demystifying Exploitable Bugs in Smart Contracts | B6: https://dl.acm.org/doi/10.1109/ICSE48619.2023.00061 | C6: Survey | D6: =Info!$B$17 -> 0 | E6: =Info!$B$19 -> 1 | F6: =Info!$B$25 -> 0.6 | G6: =Info!$B$29 -> 1 | H6: =Info!$B$35 -> 0.6 | I6: =Info!$B$40 -> 0 | J6: =Info!$B$42 -> 1 | L6: 1 | M6: Conference Proceeding or Workshop | N6: International Conference on Software Engineering | O6: 1 | P6: =(D6+E6+F6+G6+H6+I6+J6)/6 -> 0.7 | Q6: =(O6+P6)/2 -> 0.85 | R6: =IF(_xlfn.BITAND(P6>0.4999, Q6>0.4999)=1,1,0) -> 1
A7: Dynamic Vulnerability Detection on Smart Contracts Using Machine Learning | C7: PS | D7: =Info!$B$48 -> 1 | E7: =Info!$B$52 -> 0 | L7: 2 | M7: Conference Proceeding or Workshop | N7: EASE | O7: 1 | P7: =(D7+E7)/2 -> 0.5 | Q7: =(O7+P7)/2 -> 0.75 | R7: =IF(_xlfn.BITAND(P7>0.4999, Q7>0.4999)=1,1,0) -> 1
A8: Effectively Generating Vulnerable Transaction Sequences in Smart Contracts with Reinforcement Learning-guided Fuzzing | B8: https://dl.acm.org/doi/10.1145/3551349.3560429 | C8: PS | D8: 1 | E8: 1 | L8: 2,3 | M8: Conference Proceeding or Workshop | N8: ASE | O8: 1 | P8: =(D8+E8)/2 -> 1 | Q8: =(O8+P8)/2 -> 1 | R8: =IF(_xlfn.BITAND(P8>0.4999, Q8>0.4999)=1,1,0) -> 1
A9: Elysium: Context-Aware Bytecode-Level Patching to Automatically Heal Vulnerable Smart Contracts | B9: https://dl.acm.org/doi/10.1145/3545948.3545975 | C9: PS | D9: =Info!$B$48 -> 1 | E9: =Info!$B$53 -> 1 | L9: 2,3 | M9: Conference Proceeding or Workshop | N9: RAID '22: Proceedings of the 25th International Symposium on Research in Attacks, Intrusions and Defenses | O9: 0.8 | P9: =(D9+E9)/2 -> 1 | Q9: =(O9+P9)/2 -> 0.9 | R9: =IF(_xlfn.BITAND(P9>0.4999, Q9>0.4999)=1,1,0) -> 1
A10: eTainter: detecting gas-related vulnerabilities in smart contracts | B10: https://dl.acm.org/doi/10.1145/3533767.3534378 | C10: PS | D10: =Info!$B$48 -> 1 | E10: =Info!$B$53 -> 1 | L10: 2 | M10: Conference Proceeding or Workshop | N10: ISSTA 2022: Proceedings of the 31st ACM SIGSOFT International Symposium on Software Testing and Analysis | O10: 1 | P10: =(D10+E10)/2 -> 1 | Q10: =(O10+P10)/2 -> 1 | R10: =IF(_xlfn.BITAND(P10>0.4999, Q10>0.4999)=1,1,0) -> 1
A11: Eth2Vec: Learning Contract-Wide Code Representations for Vulnerability Detection on Ethereum Smart Contracts | C11: PS | D11: =Info!$B$48 -> 1 | E11: =Info!$B$53 -> 1 | L11: 2 | M11: Conference Proceeding or Workshop | N11: International Symposium on Blockchain and Secure Critical Infrastructure | O11: 0.4 | P11: =(D11+E11)/2 -> 1 | Q11: =(O11+P11)/2 -> 0.7 | R11: =IF(_xlfn.BITAND(P11>0.4999, Q11>0.4999)=1,1,0) -> 1
A12: Park: accelerating smart contract vulnerability detection via parallel-fork symbolic execution | B12: https://dl.acm.org/doi/10.1145/3533767.3534395 | C12: PS | D12: =Info!$B$51 -> 0 | E12: =Info!$B$53 -> 1 | L12: 2 | M12: Conference Proceeding or Workshop | N12: ISSTA 2022: Proceedings of the 31st ACM SIGSOFT International Symposium on Software Testing and Analysis | O12: 1 | P12: =(D12+E12)/2 -> 0.5 | Q12: =(O12+P12)/2 -> 0.75 | R12: =IF(_xlfn.BITAND(P12>0.4999, Q12>0.4999)=1,1,0) -> 1
A13: Finding permission bugs in smart contracts with role mining | B13: https://dl.acm.org/doi/10.1145/3533767.3534372 | C13: PS | D13: 1 | E13: 1 | L13: 2,3 | M13: Conference Proceeding or Workshop | N13: ISSTA 2022 | O13: 1 | P13: =(D13+E13)/2 -> 1 | Q13: =(O13+P13)/2 -> 1 | R13: =IF(_xlfn.BITAND(P13>0.4999, Q13>0.4999)=1,1,0) -> 1
A14: Siguard: Detecting Signature-Related Vulnerabilities in Smart Contracts | B14: https://dl.acm.org/doi/10.1109/ICSE-Companion58688.2023.00019 | C14: PS | D14: =Info!$B$51 -> 0 | E14: =Info!$B$53 -> 1 | L14: 2,3 | M14: Conference Proceeding or Workshop | N14: ICSE '23: Proceedings of the 45th International Conference on Software Engineering: Companion Proceedings | O14: 1 | P14: =(D14+E14)/2 -> 0.5 | Q14: =(O14+P14)/2 -> 0.75 | R14: =IF(_xlfn.BITAND(P14>0.4999, Q14>0.4999)=1,1,0) -> 1
A15: Gas estimation and optimization for smart contracts on ethereum | B15: https://dl.acm.org/doi/10.1109/ASE51524.2021.9678932 | C15: PS | D15: 1 | E15: 1 | L15: 3 | M15: Conference Proceeding or Workshop | N15: ASE21 | O15: 1 | P15: =(D15+E15)/2 -> 1 | Q15: =(O15+P15)/2 -> 1 | R15: =IF(_xlfn.BITAND(P15>0.4999, Q15>0.4999)=1,1,0) -> 1
A16: ESBMC-solidity: an SMT-based model checker for solidity smart contracts | B16: https://dl.acm.org/doi/10.1145/3510454.3516855 | C16: PS | D16: 1 | E16: 1 | M16: Conference Proceeding or Workshop | N16: ICSE22 | O16: 1 | P16: =(D16+E16)/2 -> 1 | Q16: =(O16+P16)/2 -> 1 | R16: =IF(_xlfn.BITAND(P16>0.4999, Q16>0.4999)=1,1,0) -> 1
A17: SmartState: Detecting State-Reverting Vulnerabilities in Smart Contracts via Fine-Grained State-Dependency Analysis | B17: https://dl.acm.org/doi/10.1145/3597926.3598111 | C17: PS | D17: =Info!$B$51 -> 0 | E17: =Info!$B$53 -> 1 | L17: 2,3 | M17: Conference Proceeding or Workshop | N17: ISSTA 2023: Proceedings of the 32nd ACM SIGSOFT International Symposium on Software Testing and Analysis | O17: 1 | P17: =(D17+E17)/2 -> 0.5 | Q17: =(O17+P17)/2 -> 0.75 | R17: =IF(_xlfn.BITAND(P17>0.4999, Q17>0.4999)=1,1,0) -> 1
A18: SynTest-solidity: automated test case generation and fuzzing for smart contracts | B18: https://dl.acm.org/doi/10.1145/3510454.3516869 | C18: PS | D18: =Info!$B$49 -> 0.6 | E18: =Info!$B$53 -> 1 | L18: 2.3 | M18: Conference Proceeding or Workshop | N18: ICSE '22: Proceedings of the ACM/IEEE 44th International Conference on Software Engineering: Companion Proceedings | O18: 1 | P18: =(D18+E18)/2 -> 0.8 | Q18: =(O18+P18)/2 -> 0.9 | R18: =IF(_xlfn.BITAND(P18>0.4999, Q18>0.4999)=1,1,0) -> 1
A19: Beyond “Protected” and “Private”: An Empirical Security Analysis of Custom Function Modifiers in Smart Contracts | B19: https://dl.acm.org/doi/abs/10.1145/3597926.3598125 | D19: 1 | E19: 1 | L19: 2.3 | M19: Conference Proceeding or Workshop | N19: ISSTA23 | O19: 1 | P19: =(D19+E19)/2 -> 1 | Q19: =(O19+P19)/2 -> 1 | R19: =IF(_xlfn.BITAND(P19>0.4999, Q19>0.4999)=1,1,0) -> 1
A20: When ChatGPT Meets Smart Contract Vulnerability Detection: How Far Are We? | B20: https://doi.org/10.1145/3702973 | C20: PS | D20: 1 | E20: 0 | L20: 3 | M20: Journal Article | N20: TOSEM24 | O20: 1 | P20: =(D20+E20)/2 -> 0.5 | Q20: =(O20+P20)/2 -> 0.75 | R20: =IF(_xlfn.BITAND(P20>0.4999, Q20>0.4999)=1,1,0) -> 1
A21: Improving Smart Contract Security with Contrastive Learning-based Vulnerability Detection | B21: https://doi.org/10.1145/3597503.3639173 | C21: PS | D21: 1 | E21: 1 | L21: 3 | M21: Conference Proceeding or Workshop | N21: ICSE24 | O21: 1 | P21: =(D21+E21)/2 -> 1 | Q21: =(O21+P21)/2 -> 1 | R21: =IF(_xlfn.BITAND(P21>0.4999, Q21>0.4999)=1,1,0) -> 1
A22: COBRA: Interaction-Aware Bytecode-Level Vulnerability Detector for Smart Contracts | B22: https://doi.org/10.1145/3691620.3695601 | C22: PS | D22: 0 | E22: 1 | L22: 3 | M22: Conference Proceeding or Workshop | N22: ICSE24 | O22: 1 | P22: =(D22+E22)/2 -> 0.5 | Q22: =(O22+P22)/2 -> 0.75 | R22: =IF(_xlfn.BITAND(P22>0.4999, Q22>0.4999)=1,1,0) -> 1
A23: ContractTinker: LLM-Empowered Vulnerability Repair for Real-World Smart Contracts | B23: https://doi.org/10.1145/3691620.3695349 | C23: PS | D23: 0 | E23: 1 | L23: 3 | M23: Conference Proceeding or Workshop | N23: ICSE24 | O23: 1 | P23: =(D23+E23)/2 -> 0.5 | Q23: =(O23+P23)/2 -> 0.75 | R23: =IF(_xlfn.BITAND(P23>0.4999, Q23>0.4999)=1,1,0) -> 1
A24: AdvSCanner: Generating Adversarial Smart Contracts to Exploit Reentrancy Vulnerabilities Using LLM and Static Analysis | B24: https://doi.org/10.1145/3691620.3695482 | C24: PS | D24: 0 | E24: 1 | L24: 3 | M24: Conference Proceeding or Workshop | N24: ICSE24 | O24: 1 | P24: =(D24+E24)/2 -> 0.5 | Q24: =(O24+P24)/2 -> 0.75 | R24: =IF(_xlfn.BITAND(P24>0.4999, Q24>0.4999)=1,1,0) -> 1
A25: Verifying Declarative Smart Contracts | B25: https://doi.org/10.1145/3597503.3639203 | C25: PS | D25: 0 | E25: 1 | M25: Conference Proceeding or Workshop | N25: ICSE24 | O25: 1 | P25: 0.5 | Q25: 0.75 | R25: =IF(_xlfn.BITAND(P25>0.4999, Q25>0.4999)=1,1,0) -> 1
A26: GPTScan: Detecting Logic Vulnerabilities in Smart Contracts by Combining GPT with Program Analysis | B26: https://doi.org/10.1145/3597503.3639117 | C26: PS | D26: 1 | E26: 1 | L26: 3 | M26: Conference Proceeding or Workshop | N26: ICSE24 | O26: 1 | P26: =(D26+E26)/2 -> 1 | Q26: =(O26+P26)/2 -> 1 | R26: =IF(_xlfn.BITAND(P26>0.4999, Q26>0.4999)=1,1,0) -> 1
A27: Oracle-Guided Vulnerability Diversity and Exploit Synthesis of Smart Contracts Using LLMs | B27: https://doi.org/10.1145/3691620.3695292 | C27: PS | D27: 0 | E27: 1 | L27: 3 | M27: Conference Proceeding or Workshop | N27: ICSE24 | O27: 1 | P27: =(D27+E27)/2 -> 0.5 | Q27: =(O27+P27)/2 -> 0.75 | R27: =IF(_xlfn.BITAND(P27>0.4999, Q27>0.4999)=1,1,0) -> 1
A28: FunFuzz: A Function-Oriented Fuzzer for Smart Contract Vulnerability Detection with High Effectiveness and Efficiency | B28: https://doi.org/10.1145/3674725 | C28: PS | D28: 0 | E28: 1 | L28: 3 | M28: Journal Article | N28: TOSEM24 | O28: 1 | P28: =(D28+E28)/2 -> 0.5 | Q28: =(O28+P28)/2 -> 0.75 | R28: =IF(_xlfn.BITAND(P28>0.4999, Q28>0.4999)=1,1,0) -> 1
A29: Skyeye: Detecting Imminent Attacks via Analyzing Adversarial Smart Contracts | B29: https://doi.org/10.1145/3691620.3695526 | C29: PS | D29: 0 | E29: 1 | L29: 3 | M29: Conference Proceeding or Workshop | N29: ICSE24 | O29: 1 | P29: 0.5 | Q29: 0.75 | R29: =IF(_xlfn.BITAND(P29>0.4999, Q29>0.4999)=1,1,0) -> 1
A30: Demystifying Invariant Effectiveness for Securing Smart Contracts | B30: https://doi.org/10.1145/3660786 | C30: PS | D30: 0.3 | E30: 1 | L30: 3 | M30: Conference Proceeding or Workshop | N30: ICSE24 | O30: 1 | P30: =(D30+E30)/2 -> 0.65 | Q30: =(O30+P30)/2 -> 0.825 | R30: =IF(_xlfn.BITAND(P30>0.4999, Q30>0.4999)=1,1,0) -> 1
A31: Identifying Smart Contract Security Issues in Code Snippets from Stack Overflow | B31: https://doi.org/10.1145/3650212.3680353 | C31: PS | D31: 0.3 | E31: 1 | L31: 3 | M31: Conference Proceeding or Workshop | N31: ICSE24 | O31: 1 | P31: =(D31+E31)/2 -> 0.65 | Q31: =(O31+P31)/2 -> 0.825 | R31: =IF(_xlfn.BITAND(P31>0.4999, Q31>0.4999)=1,1,0) -> 1
A32: HighGuard: Cross-Chain Business Logic Monitoring of Smart Contracts | B32: https://doi.org/10.1145/3691620.3695356 | C32: PS | E32: 1 | M32: Conference Proceeding or Workshop | N32: Proceedings of the 39th IEEE/ACM International Conference on Automated Software Engineering | O32: 1 | P32: =(D32+E32)/2 -> 0.5 | Q32: =(O32+P32)/2 -> 0.75 | R32: =IF(_xlfn.BITAND(P32>0.4999, Q32>0.4999)=1,1,0) -> 1
A33: Static Application Security Testing (SAST) Tools for Smart Contracts: How Far Are We? | B33: https://doi.org/10.1145/3660772 | C33: Survey | D33: 0 | E33: 1 | F33: 1 | G33: 0 | H33: 0 | I33: 1 | J33: 1 | L33: 2.3 | M33: Conference Proceeding or Workshop | N33: ICSE24 | O33: 1 | P33: =(D33+E33+F33+G33+H33+I33+J33)/6 -> 0.66666667 | Q33: =(O33+P33)/2 -> 0.83333333 | R33: =IF(_xlfn.BITAND(P33>0.4999, Q33>0.4999)=1,1,0) -> 1
A34: Safeguarding DeFi Smart Contracts against Oracle Deviations | B34: https://doi.org/10.1145/3597503.3639225 | C34: PS | D34: 0.6 | E34: 1 | M34: Conference Proceeding or Workshop | N34: ICSE24 | O34: 1 | P34: =(D34+E34)/2 -> 0.8 | Q34: =(O34+P34)/2 -> 0.9 | R34: =IF(_xlfn.BITAND(P34>0.4999, Q34>0.4999)=1,1,0) -> 1
A35: Midas: Mining Profitable Exploits in On-Chain Smart Contracts via Feedback-Driven Fuzzing and Differential Analysis | B35: https://doi.org/10.1145/3650212.3680321 | C35: PS | E35: 1 | M35: Conference Proceeding or Workshop | N35: Proceedings of the 33rd ACM SIGSOFT International Symposium on Software Testing and Analysis | O35: 1 | P35: =(D35+E35+F35+G35+H35+I35+J35)/2 -> 0.5 | Q35: =(O35+P35)/2 -> 0.75 | R35: =IF(_xlfn.BITAND(P35>0.4999, Q35>0.4999)=1,1,0) -> 1
A36: SmartBugs 2.0: An Execution Framework for Weakness Detection in Ethereum Smart Contracts | B36: https://doi.org/10.1109/ASE56229.2023.00060 | C36: PS | E36: 1 | M36: Conference Proceeding or Workshop | N36: Proceedings of the 38th IEEE/ACM International Conference on Automated Software Engineering | O36: 1 | P36: =(D36+E36+F36+G36+H36+I36+J36)/2 -> 0.5 | Q36: =(O36+P36)/2 -> 0.75 | R36: =IF(_xlfn.BITAND(P36>0.4999, Q36>0.4999)=1,1,0) -> 1
A37: OpenTracer: A Dynamic Transaction Trace Analyzer for Smart Contract Invariant Generation and Beyond | B37: https://doi.org/10.1145/3691620.3695361 | C37: PS | D37: 0 | E37: 1 | L37: 3 | M37: Conference Proceeding or Workshop | N37: ICSE24 | O37: 1 | P37: =(D37+E37)/2 -> 0.5 | Q37: =(O37+P37)/2 -> 0.75 | R37: =IF(_xlfn.BITAND(P37>0.4999, Q37>0.4999)=1,1,0) -> 1
A38: FunRedisp: A Function Redispatch Tool to Reduce Invocation Gas Fees in Solidity Smart Contracts | B38: https://doi.org/10.1145/3650212.3685312 | C38: PS | D38: 0 | E38: 1 | L38: 3 | M38: Conference Proceeding or Workshop | N38: ICSE24 | O38: 1 | P38: =(D38+E38)/2 -> 0.5 | Q38: =(O38+P38)/2 -> 0.75 | R38: =IF(_xlfn.BITAND(P38>0.4999, Q38>0.4999)=1,1,0) -> 1
A39: FunRedisp: Reordering Function Dispatch in Smart Contract to Reduce Invocation Gas Fees | B39: https://doi.org/10.1145/3650212.3652146 | C39: PS | D39: 0 | E39: 1 | L39: 3 | M39: Conference Proceeding or Workshop | N39: ICSE24 | O39: 1 | P39: =(D39+E39)/2 -> 0.5 | Q39: =(O39+P39)/2 -> 0.75 | R39: =IF(_xlfn.BITAND(P39>0.4999, Q39>0.4999)=1,1,0) -> 1
A40: Smart Contract Code Repair Recommendation based on Reinforcement Learning and Multi-metric Optimization | B40: https://doi.org/10.1145/3637229 | C40: PS | D40: 0.6 | E40: 1 | L40: 3 | M40: Journal Article | N40: TOSEM24 | O40: 1 | P40: =(D40+E40)/2 -> 0.8 | Q40: =(O40+P40)/2 -> 0.9 | R40: =IF(_xlfn.BITAND(P40>0.4999, Q40>0.4999)=1,1,0) -> 1
...

Sheet IEEE_Xplore
A1: Title | B1: Link | C1: Pubblication Class | D1: Q1 | E1: Q2 | F1: Q3 | G1: Q4 | H1: Q5 | I1: Q6 | J1: Q7 | K1: Exc.Crit | L1: Inc.Crit | M1: Pubblication Venue | N1: Vanue Name | O1: IDQ | P1: CDQ | Q1: FDQ | R1: Selected
A2: SCVD-SA: A Smart Contract Vulnerability Detection Method Based on Hybrid Deep Learning Model and Self-attention Mechanism | B2: https://ieeexplore.ieee.org/stamp/stamp.jsp?arnumber=10621722 | C2: PS | D2: 0 | E2: 1 | L2: 2, 3 | M2: Conference Proceeding or Workshops | N2: 2024 IEEE International Conference on Software Analysis Evolution and Reengineering - Companion (SANER-C) | O2: 1 | P2: 0.5 | Q2: 0.75 | R2: =IF(_xlfn.BITAND(P2>0.4999, Q2>0.4999)=1,1,0) -> 1
A3: FEMD: Feature Enhancement-aided Multimodal Feature Fusion Approach for Smart Contract Vulnerability Detection | B3: https://ieeexplore.ieee.org/stamp/stamp.jsp?arnumber=10763613 | C3: PS | D3: 0 | E3: 1 | L3: 2, 3 | M3: Conference Proceeding or Workshops | N3: 2024 IEEE 30th International Conference on Parallel and Distributed Systems (ICPADS) | O3: 1 | P3: 0.5 | Q3: 0.75 | R3: =IF(_xlfn.BITAND(P3>0.4999, Q3>0.4999)=1,1,0) -> 1
A4: FFGDetector: Vulnerability Detection in Cross-Contract Feature Flow Graph Using GCN | B4: https://ieeexplore.ieee.org/stamp/stamp.jsp?arnumber=10885121 | C4: PS | D4: 0 | E4: 1 | L4: 2, 3 | M4: Conference Proceeding or Workshops | N4: 2024 IEEE International Symposium on Parallel and Distributed Processing with Applications (ISPA) | O4: 0.8 | P4: 0.5 | Q4: 0.65 | R4: =IF(_xlfn.BITAND(P4>0.4999, Q4>0.4999)=1,1,0) -> 1
A5: HyWE: A Hybrid Word Embedding Method for Smart Contract Vulnerability Detection | B5: https://ieeexplore.ieee.org/stamp/stamp.jsp?arnumber=10771174 | C5: PS | D5: 0 | E5: 1 | L5: 2, 3 | M5: Conference Proceeding or Workshops | N5: 2024 IEEE 35th International Symposium on Software Reliability Engineering Workshops (ISSREW) | O5: 1 | P5: 0.5 | Q5: 0.75 | R5: =IF(_xlfn.BITAND(P5>0.4999, Q5>0.4999)=1,1,0) -> 1
A6: Smart Contract Vulnerability Detection Based on Automated Feature Extraction and Feature Interaction | B6: https://ieeexplore.ieee.org/stamp/stamp.jsp?arnumber=10319764 | C6: PS | D6: 0 | E6: 1 | L6: 2, 3 | M6: Journal Article | N6: IEEE Transactions on Knowledge and Data Engineering | O6: 1 | P6: 0.5 | Q6: 0.75 | R6: =IF(_xlfn.BITAND(P6>0.4999, Q6>0.4999)=1,1,0) -> 1
A7: Smart Contract: Tools and Challenges | B7: https://ieeexplore.ieee.org/stamp/stamp.jsp?arnumber=10530740 | C7: Review | D7: 0 | E7: 0.6 | F7: 0.6 | G7: 0.6 | H7: 0.6 | I7: 0 | J7: 1 | L7: 1, 2 | M7: Conference Proceeding or Workshops | N7: 2024 1st International Conference on Cognitive Green and Ubiquitous Computing (IC-CGU) | O7: 0.5 | P7: 0.56666667 | Q7: 0.53333333 | R7: =IF(_xlfn.BITAND(P7>0.4999, Q7>0.4999)=1,1,0) -> 1
A8: ParSE: Efficient Detection of Smart Contract Vulnerabilities via Parallel and Simplified Symbolic Execution | B8: https://ieeexplore.ieee.org/stamp/stamp.jsp?arnumber=10554916 | C8: PS | D8: 0 | E8: 1 | L8: 2, 3 | M8: Conference Proceeding or Workshops | N8: 2024 IEEE/ACM 46th International Conference on Software Engineering: Companion Proceedings (ICSE-Companion) | O8: 1 | P8: 0.5 | Q8: 0.75 | R8: =IF(_xlfn.BITAND(P8>0.4999, Q8>0.4999)=1,1,0) -> 1
A9: SCVHUNTER: Smart Contract Vulnerability Detection Based on Heterogeneous Graph Attention Network | B9: https://ieeexplore.ieee.org/stamp/stamp.jsp?arnumber=10549623 | C9: PS | D9: 0 | E9: 1 | L9: 2, 3 | M9: Conference Proceeding or Workshops | N9: 2024 IEEE/ACM 46th International Conference on Software Engineering (ICSE) | O9: 1 | P9: 0.5 | Q9: 0.75 | R9: =IF(_xlfn.BITAND(P9>0.4999, Q9>0.4999)=1,1,0) -> 1
A10: Smart Contract Vulnerability Detection with Self-Ensemble Pre-Trained Language Models | B10: https://ieeexplore.ieee.org/stamp/stamp.jsp?arnumber=10607982 | C10: PS | D10: 0 | E10: 1 | L10: 2, 3 | M10: Conference Proceeding or Workshops | N10: 2024 International Conference on Computer Information and Telecommunication Systems (CITS) | O10: 0.5 | P10: 0.5 | Q10: 0.5 | R10: =IF(_xlfn.BITAND(P10>0.4999, Q10>0.4999)=1,1,0) -> 1
A11: EVM-Shield: In-Contract State Access Control for Fast Vulnerability Detection and Prevention | B11: https://ieeexplore.ieee.org/stamp/stamp.jsp?arnumber=10380598 | C11: PS | D11: 0 | E11: 1 | L11: 2, 3 | M11: Journal Article | N11: IEEE Transactions on Information Forensics and Security | O11: 1 | P11: 0.5 | Q11: 0.75 | R11: =IF(_xlfn.BITAND(P11>0.4999, Q11>0.4999)=1,1,0) -> 1
A12: MuFuzz: Sequence-Aware Mutation and Seed Mask Guidance for Blockchain Smart Contract Fuzzing | B12: https://ieeexplore.ieee.org/stamp/stamp.jsp?arnumber=10597778 | C12: PS | D12: 0 | E12: 1 | K12: 2, 3 | M12: Conference Proceeding or Workshops | N12: 2024 IEEE 40th International Conference on Data Engineering (ICDE) | O12: 1 | P12: 0.5 | Q12: 0.75 | R12: =IF(_xlfn.BITAND(P12>0.4999, Q12>0.4999)=1,1,0) -> 1
A13: MindTheDApp: A Toolchain for Complex Network-Driven Structural Analysis of Ethereum-Based Decentralized Applications | B13: https://ieeexplore.ieee.org/stamp/stamp.jsp?arnumber=10436108 | C13: PS | D13: 0.3 | E13: 1 | K13: 2, 3 | M13: Journal Article | N13: IEEE Access | O13: 1 | P13: 0.65 | Q13: 0.825 | R13: =IF(_xlfn.BITAND(P13>0.4999, Q13>0.4999)=1,1,0) -> 1
A14: LLMSmartSec: Smart Contract Security Auditing with LLM and Annotated Control Flow Graph | B14: https://ieeexplore.ieee.org/stamp/stamp.jsp?arnumber=10664261 | C14: PS | D14: 0 | E14: 1 | K14: 2, 3 | M14: Conference Proceeding or Workshops | N14: 2024 IEEE International Conference on Blockchain (Blockchain) | O14: 0.5 | P14: 0.5 | Q14: 0.5 | R14: =IF(_xlfn.BITAND(P14>0.4999, Q14>0.4999)=1,1,0) -> 1
A15: A Systematic Review of the Blockchain Technology Security Challenges and Threats Classification | B15: https://ieeexplore.ieee.org/stamp/stamp.jsp?arnumber=10844455 | C15: SLR | D15: 1 | E15: 0.6 | F15: 0.6 | G15: 0.3 | H15: 0.3 | I15: 0 | J15: 1 | K15: 1, 2 | M15: Conference Proceeding or Workshops | N15: 2024 6th International Conference on Blockchain Computing and Applications (BCCA) | O15: 0.8 | P15: 0.63333333 | Q15: 0.71666667 | R15: =IF(_xlfn.BITAND(P15>0.4999, Q15>0.4999)=1,1,0) -> 1
A16: FELLMVP: An Ensemble LLM Framework for Classifying Smart Contract Vulnerabilities | B16: https://ieeexplore.ieee.org/stamp/stamp.jsp?arnumber=10664408 | C16: PS | D16: 0.3 | E16: 1 | K16: 2, 3 | M16: Conference Proceeding or Workshops | N16: 2024 IEEE International Conference on Blockchain (Blockchain) | O16: 0.5 | P16: 0.65 | Q16: 0.575 | R16: =IF(_xlfn.BITAND(P16>0.4999, Q16>0.4999)=1,1,0) -> 1
A17: Hunting DeFi Vulnerabilities via Context-Sensitive Concolic Verification | B17: https://ieeexplore.ieee.org/stamp/stamp.jsp?arnumber=10554973 | C17: PS | D17: 0 | E17: 1 | K17: 2, 3 | M17: Conference Proceeding or Workshops | N17: 2024 IEEE/ACM 46th International Conference on Software Engineering: Companion Proceedings (ICSE-Companion) | O17: 1 | P17: 0.5 | Q17: 0.75 | R17: =IF(_xlfn.BITAND(P17>0.4999, Q17>0.4999)=1,1,0) -> 1
A18: ContractCheck: Checking Ethereum Smart Contracts in Fine-Grained Level | B18: https://ieeexplore.ieee.org/stamp/stamp.jsp?arnumber=10531111 | C18: PS | D18: 0 | E18: 1 | K18: 2, 3 | M18: Journal Article | N18: IEEE Transactions on Software Engineering | O18: 1 | P18: 0.5 | Q18: 0.75 | R18: =IF(_xlfn.BITAND(P18>0.4999, Q18>0.4999)=1,1,0) -> 1
A19: SmartInv: Multimodal Learning for Smart Contract Invariant Inference | B19: https://ieeexplore.ieee.org/stamp/stamp.jsp?arnumber=10646885 | C19: PS | D19: 1 | E19: 1 | K19: 2, 3 | M19: Conference Proceeding or Workshops | N19: 2024 IEEE Symposium on Security and Privacy (SP) | O19: 1 | P19: 1 | Q19: 1 | R19: =IF(_xlfn.BITAND(P19>0.4999, Q19>0.4999)=1,1,0) -> 1
A20: Involuntary Transfer: A Vulnerability Pattern in Smart Contracts | B20: https://ieeexplore.ieee.org/stamp/stamp.jsp?arnumber=10385052 | C20: PS | D20: 0 | E20: 1 | K20: 2, 3 | M20: Journal Article | N20: IEEE Access | O20: 1 | P20: 0.5 | Q20: 0.75 | R20: =IF(_xlfn.BITAND(P20>0.4999, Q20>0.4999)=1,1,0) -> 1
A21: EvoFuzzer: An Evolutionary Fuzzer for Detecting Reentrancy Vulnerability in Smart Contracts | B21: https://ieeexplore.ieee.org/stamp/stamp.jsp?arnumber=10643322 | C21: PS | D21: 0 | E21: 1 | K21: 2, 3 | M21: Journal Article | N21: IEEE Transactions on Network Science and Engineering | O21: 1 | P21: 0.5 | Q21: 0.75 | R21: =IF(_xlfn.BITAND(P21>0.4999, Q21>0.4999)=1,1,0) -> 1
A22: The Sword of Damocles: Upgradeable Smart Contract in Ethereum | B22: https://ieeexplore.ieee.org/stamp/stamp.jsp?arnumber=10556443 | C22: Survey | D22: 0 | E22: 0.6 | F22: 0.6 | G22: 0.3 | H22: 0.6 | I22: 0 | J22: 1 | K22: 1, 2 | M22: Conference Proceeding or Workshops | N22: 2024 IEEE/ACM 32nd International Conference on Program Comprehension (ICPC) | O22: 1 | P22: 0.51666667 | Q22: 0.75833333 | R22: =IF(_xlfn.BITAND(P22>0.4999, Q22>0.4999)=1,1,0) -> 1
A23: Blockchain Programming Languages Vulnerabilities and Error Mitigation Strategies | B23: https://ieeexplore.ieee.org/stamp/stamp.jsp?arnumber=10645154 | C23: Survey | D23: 0 | E23: 1 | F23: 0.6 | G23: 0.3 | H23: 0.3 | I23: 0 | J23: 1 | K23: 1, 2 | M23: Conference Proceeding or Workshops | N23: 2024 11th International Conference on Electrical Electronic and Computing Engineering (IcETRAN) | O23: 0.5 | P23: 0.53333333 | Q23: 0.51666667 | R23: =IF(_xlfn.BITAND(P23>0.4999, Q23>0.4999)=1,1,0) -> 1
A24: DeFiRanger: Detecting DeFi Price Manipulation Attacks | B24: https://ieeexplore.ieee.org/stamp/stamp.jsp?arnumber=10373899 | C24: PS | D24: 0 | E24: 1 | K24: 1, 2 | M24: Journal Article | N24: IEEE Transactions on Dependable and Secure Computing | O24: 1 | P24: 0.5 | Q24: 0.75 | R24: =IF(_xlfn.BITAND(P24>0.4999, Q24>0.4999)=1,1,0) -> 1
A25: A Systematic Literature Review of Decentralized Applications in Web3: Identifying Challenges and Opportunities for Blockchain Developers | B25: https://ieeexplore.ieee.org/stamp/stamp.jsp?arnumber=10826066 | C25: SLR | D25: 1 | E25: 0.6 | F25: 0.6 | G25: 0.3 | H25: 0.6 | I25: 0 | J25: 1 | K25: 1, 2 | M25: Conference Proceeding or Workshops | N25: 2024 IEEE International Conference on Big Data (BigData) | O25: 0.8 | P25: 0.68333333 | Q25: 0.51666667 | R25: =IF(_xlfn.BITAND(P25>0.4999, Q25>0.4999)=1,1,0) -> 1
A26: Password-Authenticated Decentralized Identities | B26: https://ieeexplore.ieee.org/document/9551934 | K26: 1 | P26: =(D26+E26+F26+G26+H26+I26+J26)/7 -> 0 | Q26: =(O26+P26)/2 -> 0 | R26: =IF(_xlfn.BITAND(P26>0.4999, Q26>0.4999)=1,1,0) -> 0
A27: Using NFTs for Product Management, Digital Certification, Trading, and Delivery in the Healthcare Supply Chain | B27: https://ieeexplore.ieee.org/document/9935776 | D27: =Info!$B$17 -> 0 | E27: =Info!$B$22 -> 0 | F27: =Info!$B$27 -> 0 | G27: =Info!$B$32 -> 0 | H27: =Info!$B$37 -> 0 | I27: =Info!$B$40 -> 0 | J27: =Info!$B$43 -> 0.5 | P27: =(D27+E27+F27+G27+H27+I27+J27)/7 -> 0.071428571 | Q27: =(O27+P27)/2 -> 0.035714286 | R27: =IF(_xlfn.BITAND(P27>0.4999, Q27>0.4999)=1,1,0) -> 0
A28: Smart Contract Vulnerability Classification and Severity Approaches | B28: https://ieeexplore.ieee.org/stamp/stamp.jsp?arnumber=10583988 | M28: Conference Proceeding or Workshops | N28: 2024 IEEE Ural-Siberian Conference on Biomedical Engineering Radioelectronics and Information Technology (USBEREIT) | R28: =IF(_xlfn.BITAND(P28>0.4999, Q28>0.4999)=1,1,0) -> 0
A29: A C/C++ Smart Contract Vulnerability Detection Method Based on Intermediate Value Transformation | B29: https://ieeexplore.ieee.org/stamp/stamp.jsp?arnumber=10805477 | D29: 0 | M29: Conference Proceeding or Workshops | N29: 2024 4th International Conference on Blockchain Technology and Information Security (ICBCTIS) | R29: =IF(_xlfn.BITAND(P29>0.4999, Q29>0.4999)=1,1,0) -> 0
A30: A Survey of Vulnerability Detection Techniques by Smart Contract Tools | B30: https://ieeexplore.ieee.org/stamp/stamp.jsp?arnumber=10530990 | C30: Survey | D30: 0 | M30: Journal Article | N30: IEEE Access | O30: 1 | R30: =IF(_xlfn.BITAND(P30>0.4999, Q30>0.4999)=1,1,0) -> 0
A31: SELLM: An Integrated Tool Leveraging Symbolic Execution and LLMS for Smart Contract Vulnerability Detection | B31: https://ieeexplore.ieee.org/stamp/stamp.jsp?arnumber=10873603 | D31: 0 | M31: Conference Proceeding or Workshops | N31: 2024 21st International Computer Conference on Wavelet Active Media Technology and Information Processing (ICCWAMTIP) | R31: =IF(_xlfn.BITAND(P31>0.4999, Q31>0.4999)=1,1,0) -> 0
A32: Optimizing Smart Contract Security: A Cost-Sensitive Graph Neural Network Approach for Vulnerability Detection | B32: https://ieeexplore.ieee.org/stamp/stamp.jsp?arnumber=10846442 | D32: 0 | M32: Conference Proceeding or Workshops | N32: 2024 International Conference on Electronic Systems and Intelligent Computing (ICESIC) | R32: =IF(_xlfn.BITAND(P32>0.4999, Q32>0.4999)=1,1,0) -> 0
A33: A Survey on Security Analysis Methods of Smart Contracts | B33: https://ieeexplore.ieee.org/stamp/stamp.jsp?arnumber=10683998 | C33: Survey | D33: 0 | M33: Journal Article | N33: IEEE Transactions on Services Computing | O33: 1 | R33: =IF(_xlfn.BITAND(P33>0.4999, Q33>0.4999)=1,1,0) -> 0
A34: Usage of Static Taint Analysis and Auto Rule Generation for Smart Contract Vulnerability Detection | B34: https://ieeexplore.ieee.org/stamp/stamp.jsp?arnumber=10827343 | D34: 0 | M34: Conference Proceeding or Workshops | N34: 2024 15th International Conference on Information and Communication Technology Convergence (ICTC) | R34: =IF(_xlfn.BITAND(P34>0.4999, Q34>0.4999)=1,1,0) -> 0
A35: An Integrated Smart Contract Vulnerability Detection Tool Using Multi-Layer Perceptron on Real-Time Solidity Smart Contracts | B35: https://ieeexplore.ieee.org/stamp/stamp.jsp?arnumber=10430147 | D35: 0,3 | M35: Journal Article | N35: IEEE Access | O35: 1 | R35: =IF(_xlfn.BITAND(P35>0.4999, Q35>0.4999)=1,1,0) -> 0
A36: An Evaluation of Lightweight CNNs for Smart Contract Vulnerability Detection | B36: https://ieeexplore.ieee.org/stamp/stamp.jsp?arnumber=10634424 | C36: PS | D36: 0 | M36: Conference Proceeding or Workshops | N36: 2024 IEEE International Conference on Blockchain and Cryptocurrency (ICBC) | O36: 0,5 | R36: =IF(_xlfn.BITAND(P36>0.4999, Q36>0.4999)=1,1,0) -> 0
A37: Graph Attention Network with LSTM for Smart Contract Vulnerability Detection | B37: https://ieeexplore.ieee.org/stamp/stamp.jsp?arnumber=10795412 | M37: Conference Proceeding or Workshops | N37: 2024 Conference Proceeding or Workshop on Pervasive and Intelligent Computing (PICom) | R37: =IF(_xlfn.BITAND(P37>0.4999, Q37>0.4999)=1,1,0) -> 0
A38: ContractGNN: Ethereum Smart Contract Vulnerability Detection Based on Vulnerability Sub-Graphs and Graph Neural Networks | B38: https://ieeexplore.ieee.org/stamp/stamp.jsp?arnumber=10700860 | C38: PS | D38: 0 | E38: 1 | M38: Journal Article | N38: IEEE Transactions on Network Science and Engineering | O38: 1 | R38: =IF(_xlfn.BITAND(P38>0.4999, Q38>0.4999)=1,1,0) -> 0
A39: Design and Optimization of Smart Contracts for Cross-Domain Sharing of Sensitive Data | B39: https://ieeexplore.ieee.org/stamp/stamp.jsp?arnumber=10763577 | D39: 0 | M39: Conference Proceeding or Workshops | N39: 2024 IEEE 30th International Conference on Parallel and Distributed Systems (ICPADS) | R39: =IF(_xlfn.BITAND(P39>0.4999, Q39>0.4999)=1,1,0) -> 0
A40: The Security Paradox of Smart Contracts: Blind Spots and Prospects of Current Detection Strategies | B40: https://ieeexplore.ieee.org/stamp/stamp.jsp?arnumber=10580546 | M40: Conference Proceeding or Workshops | N40: 2024 27th International Conference on Computer Supported Cooperative Work in Design (CSCWD) | R40: =IF(_xlfn.BITAND(P40>0.4999, Q40>0.4999)=1,1,0) -> 0
...

Sheet Science_Direct
A1: Title | B1: Link | C1: Pubblication Class | D1: Q1 | E1: Q2 | F1: Q3 | G1: Q4 | H1: Q5 | I1: Q6 | J1: Q7 | K1: Exc.Crit | L1: Inc.Crit | M1: Pubblication Venue | N1: Vanue Name | O1: IDQ | P1: CDQ | Q1: FDQ | R1: Selected
A2: A security framework for Ethereum smart contracts | C2: PS | D2: =Info!$B$48 -> 1 | E2: =Info!$B$53 -> 1 | L2: 2 | M2: Journal Article | N2: Computer Communications | O2: 1 | P2: =(D2+E2)/2 -> 1 | Q2: =(O2+P2)/2 -> 1 | R2: =IF(_xlfn.BITAND(P2>0.4999, Q2>0.4999)=1,1,0) -> 1
A3: A systematic literature review of blockchain and smart contract development: Techniques, tools, and open challenges | B3: https://www.sciencedirect.com/science/article/pii/S0164121220302818 | C3: SLR | D3: =Info!$B$16 -> 1 | E3: =Info!$B$21 -> 0.3 | F3: =Info!$B$27 -> 0 | G3: =Info!$B$29 -> 1 | H3: =Info!$B$36 -> 0.3 | I3: =Info!$B$39 -> 1 | J3: =Info!$B$44 -> 0 | L3: 1.2 | M3: Journal Article | N3: Journal of Systems and Software | O3: 1 | P3: =(D3+E3+F3+G3+H3+I3+J3)/7 -> 0.51428571 | Q3: =(O3+P3)/2 -> 0.75714286 | R3: =IF(_xlfn.BITAND(P3>0.4999, Q3>0.4999)=1,1,0) -> 1
A4: Block-gram: Mining Knowledgeable Features for Smart Contract Vulnerability Detection | B4: https://www.sciencedirect.com/science/article/pii/S2352864823001347 | C4: PS | D4: =Info!$B$51 -> 0 | E4: =Info!$B$53 -> 1 | L4: 2,3 | M4: Journal Article | N4: Digital Communications and Networks | O4: 1 | P4: =(D4+E4)/2 -> 0.5 | Q4: =(O4+P4)/2 -> 0.75 | R4: =IF(_xlfn.BITAND(P4>0.4999, Q4>0.4999)=1,1,0) -> 1
A5: Combine sliced joint graph with graph neural networks for smart contract vulnerability detection | C5: PS | D5: =Info!$B$48 -> 1 | E5: =Info!$B$53 -> 1 | L5: 2,3 | M5: Journal Article | N5: Journal of Systems and Software | O5: 1 | P5: =(D5+E5)/2 -> 1 | Q5: =(O5+P5)/2 -> 1 | R5: =IF(_xlfn.BITAND(P5>0.4999, Q5>0.4999)=1,1,0) -> 1
A6: CrossFuzz: Cross-contract fuzzing for smart contract vulnerability detection | B6: https://www.sciencedirect.com/science/article/pii/S0167642323001582 | C6: PS | D6: =Info!$B$51 -> 0 | E6: =Info!$B$53 -> 1 | L6: 2,3 | M6: Journal Article | N6: Science of Computer Programming | O6: 0.5 | P6: =(D6+E6)/2 -> 0.5 | Q6: =(O6+P6)/2 -> 0.5 | R6: =IF(_xlfn.BITAND(P6>0.4999, Q6>0.4999)=1,1,0) -> 1
A7: Effuzz: Efficient fuzzing by directed search for smart contracts | B7: https://www.sciencedirect.com/science/article/pii/S0950584923000678 | C7: PS | D7: =Info!$B$51 -> 0 | E7: =Info!$B$53 -> 1 | L7: 2,3 | M7: Journal Article | N7: Information and Software Technology | O7: 1 | P7: =(D7+E7)/2 -> 0.5 | Q7: =(O7+P7)/2 -> 0.75 | R7: =IF(_xlfn.BITAND(P7>0.4999, Q7>0.4999)=1,1,0) -> 1
A8: Enhancing Ethereum smart-contracts static analysis by computing a precise Control-Flow Graph of Ethereum bytecode | B8: https://www.sciencedirect.com/science/article/pii/S0164121223000481 | C8: PS | D8: =Info!$B$51 -> 0 | E8: =Info!$B$53 -> 1 | L8: 1 | M8: Journal Article | N8: Journal of Systems and Software | O8: 1 | P8: =(D8+E8)/2 -> 0.5 | Q8: =(O8+P8)/2 -> 0.75 | R8: =IF(_xlfn.BITAND(P8>0.4999, Q8>0.4999)=1,1,0) -> 1
A9: Smart contract vulnerability detection combined with multi-objective detection | B9: https://www.sciencedirect.com/science/article/abs/pii/S1389128622003437 | C9: PS | D9: =Info!$B$48 -> 1 | E9: =Info!$B$53 -> 1 | L9: 2 | M9: Journal Article | N9: Computer Networks | O9: 1 | P9: =(D9+E9)/2 -> 1 | Q9: =(O9+P9)/2 -> 1 | R9: =IF(_xlfn.BITAND(P9>0.4999, Q9>0.4999)=1,1,0) -> 1
A10: SolGuard: Preventing external call issues in smart contract-based multi-agent robotic systems | B10: https://www.sciencedirect.com/science/article/pii/S0020025521007994 | C10: PS | D10: =Info!$B$17 -> 0 | E10: 1 | L10: 2 | M10: Journal Article | N10: Information Sciences | O10: 1 | P10: =(D10+E10)/2 -> 0.5 | Q10: =(O10+P10)/2 -> 0.75 | R10: =IF(_xlfn.BITAND(P10>0.4999, Q10>0.4999)=1,1,0) -> 1
A11: SVScanner: Detecting smart contract vulnerabilities via deep semantic extraction | B11: https://www.sciencedirect.com/science/article/abs/pii/S2214212623000686 | C11: PS | D11: =Info!$B$50 -> 0.3 | E11: =Info!$B$53 -> 1 | L11: 2,3 | M11: Journal Article | N11: Journal of Information Security and Applications | O11: 1 | P11: =(D11+E11)/2 -> 0.65 | Q11: =(O11+P11)/2 -> 0.825 | R11: =IF(_xlfn.BITAND(P11>0.4999, Q11>0.4999)=1,1,0) -> 1
A12: Unveiling Vulnerable Smart Contracts: Toward Profiling Vulnerable Smart Contracts using Genetic Algorithm and Generating Benchmark Dataset | B12: https://www.sciencedirect.com/science/article/pii/S2096720923000465 | C12: PS | D12: =Info!$B$51 -> 0 | E12: =Info!$B$53 -> 1 | L12: 2 | M12: Arxiv Paper or Preprint | N12: Blockchain: Research and Applications | O12: 1 | P12: =(D12+E12)/2 -> 0.5 | Q12: 0.8 | R12: =IF(_xlfn.BITAND(P12>0.4999, Q12>0.4999)=1,1,0) -> 1
A13: Vulpedia: Detecting vulnerable ethereum smart contracts via abstracted vulnerability signatures | C13: PS | D13: =Info!$B$49 -> 0.6 | E13: =Info!$B$53 -> 1 | L13: 2,3 | M13: Journal Article | N13: Journal of Systems and Software | O13: 1 | P13: =(D13+E13)/2 -> 0.8 | Q13: =(O13+P13)/2 -> 0.9 | R13: =IF(_xlfn.BITAND(P13>0.4999, Q13>0.4999)=1,1,0) -> 1
A14: Unveiling Smart Contracts Vulnerabilities: Toward Profiling Smart Contracts Vulnerabilities using Enhanced Genetic Algorithm and Generating Benchmark Dataset | B14: https://www.sciencedirect.com/science/article/pii/S2096720924000666 | C14: PS | D14: 0 | E14: 1 | M14: Journal Article | N14: Blockchain: Research and Applications | O14: 1 | P14: =(D14+E14+F14+G14+H14+I14+J14)/2 -> 0.5 | Q14: =(O14+P14)/2 -> 0.75 | R14: =IF(_xlfn.BITAND(P14>0.4999, Q14>0.4999)=1,1,0) -> 1
A15: A comprehensive survey of smart contracts vulnerability detection tools: Techniques and methodologies | B15: https://www.sciencedirect.com/science/article/pii/S1084804525000396 | C15: SLR | D15: 1 | E15: 0.6 | F15: 0.6 | G15: 1 | H15: 1 | I15: 0 | J15: 1 | M15: Journal Article | N15: Journal of Network and Computer Applications | O15: 1 | P15: =(D15+E15+F15+G15+H15+I15+J15)/7 -> 0.74285714 | Q15: =(O15+P15)/2 -> 0.87142857 | R15: =IF(_xlfn.BITAND(P15>0.4999, Q15>0.4999)=1,1,0) -> 1
A16: Smart contracts vulnerability detection model based on adversarial multi-task learning | B16: https://www.sciencedirect.com/science/article/pii/S2214212623001394 | C16: PS | D16: =Info!$B$51 -> 0 | E16: =Info!$B$54 -> 0 | L16: 2 | M16: Journal Article | N16: Journal of Information Security and Applications | O16: 1 | P16: =(D16+E16)/2 -> 0 | Q16: =(O16+P16)/2 -> 0.5 | R16: =IF(_xlfn.BITAND(P16>0.4999, Q16>0.4999)=1,1,0) -> 0
A17: Vulnerable smart contract function locating based on Multi-Relational Nested Graph Convolutional Network | B17: https://www.sciencedirect.com/science/article/abs/pii/S016412122300170X | C17: PS | D17: =Info!$B$51 -> 0 | E17: =Info!$B$54 -> 0 | L17: 1 | M17: Journal Article | N17: Journal of Information Security and Applications | O17: 1 | P17: =(D17+E17)/2 -> 0 | Q17: =(O17+P17)/2 -> 0.5 | R17: =IF(_xlfn.BITAND(P17>0.4999, Q17>0.4999)=1,1,0) -> 0
A18: A formal verification approach for composite smart contracts security using FSM | B18: https://www.sciencedirect.com/science/article/pii/S1319157822003111 | C18: PS | D18: =Info!$B$50 -> 0.3 | E18: =Info!$B$54 -> 0 | L18: 1 | M18: Journal Article | N18: Journal of King Saud University - Computer and Information Sciences | O18: 1 | P18: =(D18+E18+F18+G18+H18+I18+J18)/6 -> 0.05 | Q18: =(O18+P18)/2 -> 0.525 | R18: =IF(_xlfn.BITAND(P18>0.4999, Q18>0.4999)=1,1,0) -> 0
A19: A survey of DeFi security: Challenges and opportunities | B19: https://www.sciencedirect.com/science/article/pii/S1319157822003792 | C19: Survey | D19: =Info!$B$16 -> 1 | E19: =Info!$B$20 -> 0.6 | F19: =Info!$B$25 -> 0.6 | G19: =Info!$B$32 -> 0 | H19: =Info!$B$37 -> 0 | I19: =Info!$B$40 -> 0 | J19: =Info!$B$43 -> 0.5 | L19: 1 | M19: Journal Article | N19: Journal of King Saud University - Computer and Information Sciences | O19: 1 | P19: =(D19+E19+F19+G19+H19+I19+J19)/6 -> 0.45 | Q19: =(O19+P19)/2 -> 0.725 | R19: =IF(_xlfn.BITAND(P19>0.4999, Q19>0.4999)=1,1,0) -> 0
A20: A survey on blockchain technology and its security | B20: https://www.sciencedirect.com/science/article/pii/S2096720922000070 | C20: Survey | D20: =Info!$B$17 -> 0 | E20: =Info!$B$20 -> 0.6 | F20: =Info!$B$26 -> 0.3 | G20: =Info!$B$31 -> 0.3 | H20: =Info!$B$36 -> 0.3 | I20: =Info!$B$40 -> 0 | J20: =Info!$B$43 -> 0.5 | L20: 1 | M20: Journal Article | N20: Blockchain: Research and Applications | O20: 1 | P20: =(D20+E20+F20+G20+H20+I20+J20)/6 -> 0.33333333 | Q20: =(O20+P20)/2 -> 0.66666667 | R20: =IF(_xlfn.BITAND(P20>0.4999, Q20>0.4999)=1,1,0) -> 0
